Workbook

Sheet Instructions
A1: Expert Reference Set – Simple Workflow
A3: Purpose: create an independent expert reference set before evaluating the LLM.
A5: Step | B5: What to do | D5: Term | E5: Meaning
A6: 1 | B6: Expert A and Expert B complete their own sheets independently | D6: Direct | E6: A suitable database process represents the same material/product sufficiently well. | G6: 5
A7: 2 | B7: For each BOM item, write a normalized material name. Then select the best process from ELCD_Catalog and the UUID fills automatically. | D7: Proxy | E7: No direct process exists, but a technically defensible substitute is available.
A8: 3 | B8: Choose Direct, Proxy, or Review Required. Use Review Required ONLY when no usable ELCD process is available. If an ELCD process is selected as a substitute rather than an exact match, classify it as Proxy. | D8: Review Required | E8: No usable ELCD process is available. These are the only items eligible for the LLM fallback stage.
A9: 4 | B9: After both experts finish, use Reconciliation to create the final reference answer. Any field on which both experts agree is carried forward automatically, and reconcile only the remaining blank final fields. Only after all required final fields are resolved should LLM scoring begin. | D9: Confidence | E9: High = clear, Medium = judgment required, Low = substantial uncertainty.
A11: Important: ELCD_Catalog contains the 608 processes exported from the active openLCA database. Experts should select only from this catalog and should not estimate emission factors. | B11: Important: ELCD_Catalog contains the exported openLCA processes. Direct = suitable ELCD representation; Proxy = selected ELCD substitute; Review Required = process unavailable. Experts should not estimate emission factors here.

Sheet Expert_A
A1: Expert A – Independent Expert Review
A4: ID | B4: Case Study | C4: Original BOM Description | D4: Qty. | E4: Unit | F4: Normalized Material | G4: Best ELCD/openLCA Process (select from catalog) | H4: Process UUID (auto) | I4: Match Type | J4: Confidence | K4: Brief Notes / Rationale
A5: S01 | B5: Stonecrete House | C5: Ordinary Portland Cement (OPC 43-grade) | D5: 5000 | E5: kg | F5: Cement | G5: Portland cement (CEM I), CEMBUREAU production mix, at plant, CEMBUREAU technology mix, EN 197-1 | RER | 600573dd | H5: =IF(G5="","",IFERROR(VLOOKUP(G5,ELCD_Catalog!$A$2:$B$609,2,FALSE),"")) -> 600573dd-dfa5-44e5-b458-8727e793ffd7 | I5: Direct | J5: High
A6: S02 | B6: Stonecrete House | C6: River Sand (clean, well-graded) | D6: 24000 | E6: kg | F6: Sand | G6: Sand 0/2, production mix, at plant, wet and dry quarry, undried | RER | 898618b1 | H6: =IF(G6="","",IFERROR(VLOOKUP(G6,ELCD_Catalog!$A$2:$B$609,2,FALSE),"")) -> 898618b1-3306-11dd-bd11-0800200c9a66 | I6: Direct | J6: High
A7: S03 | B7: Stonecrete House | C7: Natural Gravel | D7: 12 | E7: m³ | F7: Gravel | G7: Gravel 2/32, production mix, at plant, wet and dry quarry, undried | RER | 898618b2 | H7: =IF(G7="","",IFERROR(VLOOKUP(G7,ELCD_Catalog!$A$2:$B$609,2,FALSE),"")) -> 898618b2-3306-11dd-bd11-0800200c9a66 | I7: Direct | J7: High
A8: S04 | B8: Stonecrete House | C8: Stone | D8: 12 | E8: m³ | F8: Stone | G8: Crushed stone 16/32, production mix, at plant, open pit mining, undried | RER | 898618b3 | H8: =IF(G8="","",IFERROR(VLOOKUP(G8,ELCD_Catalog!$A$2:$B$609,2,FALSE),"")) -> 898618b3-3306-11dd-bd11-0800200c9a66 | I8: Proxy | J8: Medium | K8: Not entirely sure about types of stone
A9: S05 | B9: Stonecrete House | C9: Plain Cement Concrete (PCC M10 — 1:3:6) - Binding Layer | D9: 1.6 | E9: m³ | F9: Concrete | G9: Pre-cast concrete, production mix, at plant, minimum reinforcement, concrete type C20/25, without consideration of casings | RER | 898618b0 | H9: =IF(G9="","",IFERROR(VLOOKUP(G9,ELCD_Catalog!$A$2:$B$609,2,FALSE),"")) -> 898618b0-3306-11dd-bd11-0800200c9a66 | I9: Direct | J9: High
A10: S06 | B10: Stonecrete House | C10: Stonecrete block | D10: 3512.34 | E10: kg | F10: Concrete block | G10: Gypsum stone (CaSO4-dihydrate), production mix, at plant, underground and open pit mining, grinded and purified product | DE | 5adbdfe6 | H10: =IF(G10="","",IFERROR(VLOOKUP(G10,ELCD_Catalog!$A$2:$B$609,2,FALSE),"")) -> 5adbdfe6-401f-4dfa-a3ec-1699064adb34 | I10: Proxy | J10: Low | K10: Note sure about the types of stone slected.
A11: S07 | B11: Stonecrete House | C11: Rebar TMT Fe500 | D11: 250 | E11: kg | F11: Rebar | G11: Steel rebar, production mix, at plant, blast furnace and electric arc furnace route, | GLO | 268a11fb | H11: =IF(G11="","",IFERROR(VLOOKUP(G11,ELCD_Catalog!$A$2:$B$609,2,FALSE),"")) -> 268a11fb-baf2-4b9e-8867-38bea0e76ef6 | I11: Direct | J11: High
A12: S08 | B12: Stonecrete House | C12: Binding Wire (soft annealed, 18-gauge) | D12: 5 | E12: kg | F12: Wire | G12: Copper wire, consumption mix, at plant, technology mix, cross section 1 mmy | EU-15 | 11bceac4 | H12: =IF(G12="","",IFERROR(VLOOKUP(G12,ELCD_Catalog!$A$2:$B$609,2,FALSE),"")) -> 11bceac4-b3d8-4048-8e80-b691ecd2c261 | I12: Proxy | J12: Low | K12: Unsure about materials types, either steel or copper or others
A13: S09 | B13: Stonecrete House | C13: Corrugated Galvanized Iron (CGI) Sheet, 0.45 mm BMT | D13: 190.71 | E13: kg | F13: Steel Rolls | G13: Steel hot rolled section, production mix, at plant, blast furnace and electric arc furnace route, | GLO | f9d4581e | H13: =IF(G13="","",IFERROR(VLOOKUP(G13,ELCD_Catalog!$A$2:$B$609,2,FALSE),"")) -> f9d4581e-14de-417e-8f9f-6c74e6f14051 | I13: Proxy | J13: Low | K13: review required as not clear if it is EAF or blast furnace
A14: S10 | B14: Stonecrete House | C14: Timber for purlin, rafter, and column post | D14: 2.08 | E14: m³ | F14: Timber | G14: Spruce wood, production mix, at saw mill, timber, 40% water content | DE | 2b61a4d6 | H14: =IF(G14="","",IFERROR(VLOOKUP(G14,ELCD_Catalog!$A$2:$B$609,2,FALSE),"")) -> 2b61a4d6-bd1d-4ea3-828c-fdbdf5fca1f9 | I14: Proxy | J14: Medium | K14: which wood unsure
A15: S11 | B15: Stonecrete House | C15: Plaster 1:4 — External Walls, 15 mm thick | D15: 65 | E15: m² | F15: Plaster | G15: Not available | H15: =IF(G15="","",IFERROR(VLOOKUP(G15,ELCD_Catalog!$A$2:$B$609,2,FALSE),"")) | I15: Review Required | J15: Low
A16: S12 | B16: Stonecrete House | C16: Plaster 1:6 — Internal Walls, 12 mm thick | D16: 128 | E16: m² | F16: Plaster | G16: Not available | H16: =IF(G16="","",IFERROR(VLOOKUP(G16,ELCD_Catalog!$A$2:$B$609,2,FALSE),"")) | I16: Review Required | J16: Low
A17: B01 | B17: Bamboo House | C17: Cement | D17: 1250 | E17: kg | F17: Cement | G17: Portland cement (CEM I), CEMBUREAU production mix, at plant, CEMBUREAU technology mix, EN 197-1 | RER | 600573dd | H17: =IF(G17="","",IFERROR(VLOOKUP(G17,ELCD_Catalog!$A$2:$B$609,2,FALSE),"")) -> 600573dd-dfa5-44e5-b458-8727e793ffd7 | I17: Direct | J17: High
A18: B02 | B18: Bamboo House | C18: Sand | D18: 9600 | E18: kg | F18: Sand | G18: Sand 0/2, production mix, at plant, wet and dry quarry, undried | RER | 898618b1 | H18: =IF(G18="","",IFERROR(VLOOKUP(G18,ELCD_Catalog!$A$2:$B$609,2,FALSE),"")) -> 898618b1-3306-11dd-bd11-0800200c9a66 | I18: Direct | J18: High
A19: B03 | B19: Bamboo House | C19: Natural Gravel | D19: 6 | E19: m³ | F19: Gravel | G19: Gravel 2/32, production mix, at plant, wet and dry quarry, undried | RER | 898618b2 | H19: =IF(G19="","",IFERROR(VLOOKUP(G19,ELCD_Catalog!$A$2:$B$609,2,FALSE),"")) -> 898618b2-3306-11dd-bd11-0800200c9a66 | I19: Direct | J19: High
A20: B04 | B20: Bamboo House | C20: Stone | D20: 9 | E20: m³ | F20: Stone | G20: Crushed stone 16/32, production mix, at plant, open pit mining, undried | RER | 898618b3 | H20: =IF(G20="","",IFERROR(VLOOKUP(G20,ELCD_Catalog!$A$2:$B$609,2,FALSE),"")) -> 898618b3-3306-11dd-bd11-0800200c9a66 | I20: Proxy | J20: Medium | K20: Not entirely sure about types of stone
A21: B05 | B21: Bamboo House | C21: Soil | D21: 12 | E21: m³ | F21: Soil | G21: Not available | H21: =IF(G21="","",IFERROR(VLOOKUP(G21,ELCD_Catalog!$A$2:$B$609,2,FALSE),"")) | I21: Review Required | J21: Low | K21: Not available; needs research
A22: B06 | B22: Bamboo House | C22: Local Wood | D22: 0.21 | E22: m³ | F22: Wood | G22: Pine wood, production mix, at saw mill, timber, 40% water content | DE | 621e64d0 | H22: =IF(G22="","",IFERROR(VLOOKUP(G22,ELCD_Catalog!$A$2:$B$609,2,FALSE),"")) -> 621e64d0-f471-4023-9ebc-a52cd8ee573f | I22: Proxy | J22: Medium
A23: B07 | B23: Bamboo House | C23: 19mm Plywood | D23: 4 | E23: m² | F23: Plywood | G23: Pine wood, production mix, at saw mill, timber, 40% water content | DE | 621e64d0 | H23: =IF(G23="","",IFERROR(VLOOKUP(G23,ELCD_Catalog!$A$2:$B$609,2,FALSE),"")) -> 621e64d0-f471-4023-9ebc-a52cd8ee573f | I23: Proxy | J23: Low | K23: No possible plywood located.
A24: B08 | B24: Bamboo House | C24: Nail | D24: 2 | E24: kg | F24: Steel nail | G24: Not available | H24: =IF(G24="","",IFERROR(VLOOKUP(G24,ELCD_Catalog!$A$2:$B$609,2,FALSE),"")) | I24: Review Required | J24: Low | K24: No possible proxy data match for nail.
A25: B09 | B25: Bamboo House | C25: 10mm Rebar | D25: 116 | E25: kg | F25: Rebar | G25: Steel rebar, production mix, at plant, blast furnace and electric arc furnace route, | GLO | 268a11fb | H25: =IF(G25="","",IFERROR(VLOOKUP(G25,ELCD_Catalog!$A$2:$B$609,2,FALSE),"")) -> 268a11fb-baf2-4b9e-8867-38bea0e76ef6 | I25: Direct | J25: High
A26: B10 | B26: Bamboo House | C26: 7mm Rebar | D26: 51 | E26: kg | F26: Rebar | G26: Steel rebar, production mix, at plant, blast furnace and electric arc furnace route, | GLO | 268a11fb | H26: =IF(G26="","",IFERROR(VLOOKUP(G26,ELCD_Catalog!$A$2:$B$609,2,FALSE),"")) -> 268a11fb-baf2-4b9e-8867-38bea0e76ef6 | I26: Direct | J26: High
A27: B11 | B27: Bamboo House | C27: Binding Wire | D27: 4 | E27: kg | F27: Wire | G27: Copper wire; technology mix; market mix, at plant; cross section 1 mm, Technology and Market Mix for Wire fabrication representing main European production countries, Market Mix for Copper cathode in Europe (primary and secondary Cu cathode production... | EU-25 | 819e60d3 | H27: =IF(G27="","",IFERROR(VLOOKUP(G27,ELCD_Catalog!$A$2:$B$609,2,FALSE),"")) | I27: Proxy | J27: Low | K27: Unsure about materials types, either steel or copper or others
A28: B12 | B28: Bamboo House | C28: 24 Gauge CGI Sheets | D28: 630 | E28: kg | F28: Steel Rolls | G28: Steel hot rolled coil, production mix, at plant, blast furnace route, thickness 2 to 7 mm, width 600 to 2100 mm | RER | 119e8cc1 | H28: =IF(G28="","",IFERROR(VLOOKUP(G28,ELCD_Catalog!$A$2:$B$609,2,FALSE),"")) -> 119e8cc1-0859-45ca-8f63-93a8a518ffd2 | I28: Proxy | J28: Medium | K28: review required as not clear if it is EAF or blast furnace
A29: B13 | B29: Bamboo House | C29: 3mm Commercial Plywood | D29: 3 | E29: m² | F29: Plywood | G29: Pine wood, production mix, at saw mill, timber, 40% water content | DE | 621e64d0 | H29: =IF(G29="","",IFERROR(VLOOKUP(G29,ELCD_Catalog!$A$2:$B$609,2,FALSE),"")) -> 621e64d0-f471-4023-9ebc-a52cd8ee573f | I29: Proxy | J29: Low | K29: No possible plywood located.
A30: B14 | B30: Bamboo House | C30: Bamboo | D30: 4.82 | E30: m³ | F30: Bamboo | G30: Not available | H30: =IF(G30="","",IFERROR(VLOOKUP(G30,ELCD_Catalog!$A$2:$B$609,2,FALSE),"")) | I30: Review Required | J30: Low | K30: Not available; needs research
A31: A01 | B31: Bamboo House with Attic | C31: Cement | D31: 7300 | E31: kg | F31: Cement | G31: Portland cement (CEM I), CEMBUREAU production mix, at plant, CEMBUREAU technology mix, EN 197-1 | RER | 600573dd | H31: =IF(G31="","",IFERROR(VLOOKUP(G31,ELCD_Catalog!$A$2:$B$609,2,FALSE),"")) -> 600573dd-dfa5-44e5-b458-8727e793ffd7 | I31: Direct | J31: High
A32: A02 | B32: Bamboo House with Attic | C32: Sand | D32: 27200 | E32: kg | F32: Sand | G32: Sand 0/2, production mix, at plant, wet and dry quarry, undried | RER | 898618b1 | H32: =IF(G32="","",IFERROR(VLOOKUP(G32,ELCD_Catalog!$A$2:$B$609,2,FALSE),"")) -> 898618b1-3306-11dd-bd11-0800200c9a66 | I32: Direct | J32: High
A33: A03 | B33: Bamboo House with Attic | C33: Natural Gravel | D33: 6 | E33: m³ | F33: Gravel | G33: Gravel 2/32, production mix, at plant, wet and dry quarry, undried | RER | 898618b2 | H33: =IF(G33="","",IFERROR(VLOOKUP(G33,ELCD_Catalog!$A$2:$B$609,2,FALSE),"")) -> 898618b2-3306-11dd-bd11-0800200c9a66 | I33: Direct | J33: High
A34: A04 | B34: Bamboo House with Attic | C34: Soil Blocks | D34: 6042 | E34: Nos. | F34: Soil | G34: Not available | H34: =IF(G34="","",IFERROR(VLOOKUP(G34,ELCD_Catalog!$A$2:$B$609,2,FALSE),"")) | I34: Review Required | J34: Low | K34: Not available; needs research
A35: A05 | B35: Bamboo House with Attic | C35: Wood | D35: 0.264 | E35: m³ | F35: Wood | G35: Spruce wood, production mix, at saw mill, timber, 40% water content | DE | 2b61a4d6 | H35: =IF(G35="","",IFERROR(VLOOKUP(G35,ELCD_Catalog!$A$2:$B$609,2,FALSE),"")) -> 2b61a4d6-bd1d-4ea3-828c-fdbdf5fca1f9 | I35: Direct | J35: High
A36: A06 | B36: Bamboo House with Attic | C36: Bamboo | D36: 5.915 | E36: m³ | F36: Bamboo | G36: Not available | H36: =IF(G36="","",IFERROR(VLOOKUP(G36,ELCD_Catalog!$A$2:$B$609,2,FALSE),"")) | I36: Review Required | J36: Low | K36: Not available; needs research
A37: A07 | B37: Bamboo House with Attic | C37: Rebar | D37: 674 | E37: kg | F37: Rebar | G37: Steel rebar, production mix, at plant, blast furnace and electric arc furnace route, | GLO | 268a11fb | H37: =IF(G37="","",IFERROR(VLOOKUP(G37,ELCD_Catalog!$A$2:$B$609,2,FALSE),"")) -> 268a11fb-baf2-4b9e-8867-38bea0e76ef6 | I37: Direct | J37: High
A38: A08 | B38: Bamboo House with Attic | C38: Soil | D38: 3 | E38: m³ | F38: Soil | G38: Not available | H38: =IF(G38="","",IFERROR(VLOOKUP(G38,ELCD_Catalog!$A$2:$B$609,2,FALSE),"")) | I38: Review Required | J38: Low | K38: Not available; needs research
A39: A09 | B39: Bamboo House with Attic | C39: CGI Sheets | D39: 478.07 | E39: kg | F39: Steel Rolls | G39: Steel hot rolled coil, production mix, at plant, blast furnace route, thickness 2 to 7 mm, width 600 to 2100 mm | RER | 119e8cc1 | H39: =IF(G39="","",IFERROR(VLOOKUP(G39,ELCD_Catalog!$A$2:$B$609,2,FALSE),"")) -> 119e8cc1-0859-45ca-8f63-93a8a518ffd2 | I39: Proxy | J39: Medium | K39: review required as not clear if it is EAF or blast furnace

Sheet Expert_B
A1: Expert B – Independent Expert Review
A4: ID | B4: Case Study | C4: Original BOM Description | D4: Qty. | E4: Unit | F4: Normalized Material | G4: Best ELCD/openLCA Process (select from catalog) | H4: Process UUID (auto) | I4: Match Type | J4: Confidence | K4: Brief Notes / Rationale
A5: S01 | B5: Stonecrete House | C5: Ordinary Portland Cement (OPC 43-grade) | D5: 5000 | E5: kg | F5: Cement | G5: Portland cement (CEM I), CEMBUREAU production mix, at plant, CEMBUREAU technology mix, EN 197-1 | RER | 600573dd | H5: =IF(G5="","",IFERROR(VLOOKUP(G5,ELCD_Catalog!$A$2:$B$609,2,FALSE),"")) -> 600573dd-dfa5-44e5-b458-8727e793ffd7 | I5: Direct | J5: High
A6: S02 | B6: Stonecrete House | C6: River Sand (clean, well-graded) | D6: 24000 | E6: kg | F6: Sand | G6: Sand 0/2, production mix, at plant, wet and dry quarry, undried | RER | 898618b1 | H6: =IF(G6="","",IFERROR(VLOOKUP(G6,ELCD_Catalog!$A$2:$B$609,2,FALSE),"")) -> 898618b1-3306-11dd-bd11-0800200c9a66 | I6: Direct | J6: High
A7: S03 | B7: Stonecrete House | C7: Natural Gravel | D7: 12 | E7: m³ | F7: Gravel | G7: Gravel 2/32, production mix, at plant, wet and dry quarry, undried | RER | 898618b2 | H7: =IF(G7="","",IFERROR(VLOOKUP(G7,ELCD_Catalog!$A$2:$B$609,2,FALSE),"")) -> 898618b2-3306-11dd-bd11-0800200c9a66 | I7: Direct | J7: High
A8: S04 | B8: Stonecrete House | C8: Stone | D8: 12 | E8: m³ | F8: Stone | G8: Crushed stone 16/32, production mix, at plant, open pit mining, undried | RER | 898618b3 | H8: =IF(G8="","",IFERROR(VLOOKUP(G8,ELCD_Catalog!$A$2:$B$609,2,FALSE),"")) -> 898618b3-3306-11dd-bd11-0800200c9a66 | I8: Direct | J8: High
A9: S05 | B9: Stonecrete House | C9: Plain Cement Concrete (PCC M10 — 1:3:6) - Binding Layer | D9: 1.6 | E9: m³ | F9: Concrete | G9: Pre-cast concrete, production mix, at plant, minimum reinforcement, concrete type C20/25, without consideration of casings | RER | 898618b0 | H9: =IF(G9="","",IFERROR(VLOOKUP(G9,ELCD_Catalog!$A$2:$B$609,2,FALSE),"")) -> 898618b0-3306-11dd-bd11-0800200c9a66 | I9: Proxy | J9: Medium
A10: S06 | B10: Stonecrete House | C10: Stonecrete block | D10: 3512.34 | E10: kg | F10: Block | G10: Lightweight concrete block, production mix, at plant, expanded clay as base material | RER | 898618b6 | H10: =IF(G10="","",IFERROR(VLOOKUP(G10,ELCD_Catalog!$A$2:$B$609,2,FALSE),"")) -> 898618b6-3306-11dd-bd11-0800200c9a66 | I10: Proxy | J10: Medium
A11: S07 | B11: Stonecrete House | C11: Rebar TMT Fe500 | D11: 250 | E11: kg | F11: Rebar | G11: Steel rebar, production mix, at plant, blast furnace and electric arc furnace route, | GLO | 268a11fb | H11: =IF(G11="","",IFERROR(VLOOKUP(G11,ELCD_Catalog!$A$2:$B$609,2,FALSE),"")) -> 268a11fb-baf2-4b9e-8867-38bea0e76ef6 | I11: Direct | J11: Medium
A12: S08 | B12: Stonecrete House | C12: Binding Wire (soft annealed, 18-gauge) | D12: 5 | E12: kg | F12: Wire | G12: Copper wire, consumption mix, at plant, technology mix, cross section 1 mmy | EU-15 | 11bceac4 | H12: =IF(G12="","",IFERROR(VLOOKUP(G12,ELCD_Catalog!$A$2:$B$609,2,FALSE),"")) -> 11bceac4-b3d8-4048-8e80-b691ecd2c261 | I12: Proxy | J12: Medium
A13: S09 | B13: Stonecrete House | C13: Corrugated Galvanized Iron (CGI) Sheet, 0.45 mm BMT | D13: 190.71 | E13: kg | F13: CGI Sheets | G13: corrugated board sheets, production mix, at plant, technology mix, 18% primary fibre, 82 % recycled fibre | EU-27 | 7311da1a | H13: =IF(G13="","",IFERROR(VLOOKUP(G13,ELCD_Catalog!$A$2:$B$609,2,FALSE),"")) -> 7311da1a-673f-96b5-66ef-00004409928e | I13: Proxy | J13: Low
A14: S10 | B14: Stonecrete House | C14: Timber for purlin, rafter, and column post | D14: 2.08 | E14: m³ | F14: Timber | G14: Pine wood, production mix, at saw mill, timber, 40% water content | DE | 621e64d0 | H14: =IF(G14="","",IFERROR(VLOOKUP(G14,ELCD_Catalog!$A$2:$B$609,2,FALSE),"")) -> 621e64d0-f471-4023-9ebc-a52cd8ee573f | I14: Proxy | J14: Medium
A15: S11 | B15: Stonecrete House | C15: Plaster 1:4 — External Walls, 15 mm thick | D15: 65 | E15: m² | F15: Plaster | G15: Not available | H15: =IF(G15="","",IFERROR(VLOOKUP(G15,ELCD_Catalog!$A$2:$B$609,2,FALSE),"")) | I15: Review Required | J15: Low
A16: S12 | B16: Stonecrete House | C16: Plaster 1:6 — Internal Walls, 12 mm thick | D16: 128 | E16: m² | F16: Plaster | G16: Not available | H16: =IF(G16="","",IFERROR(VLOOKUP(G16,ELCD_Catalog!$A$2:$B$609,2,FALSE),"")) | I16: Review Required | J16: Low
... A39: A09 | B39: Bamboo House with Attic | C39: CGI Sheets | D39: 478.07 | E39: kg | F39: CGI Sheets | G39: corrugated board sheets, production mix, at plant, technology mix, 18% primary fibre, 82 % recycled fibre | EU-27 | 7311da1a | H39: =IF(G39="","",IFERROR(VLOOKUP(G39,ELCD_Catalog!$A$2:$B$609,2,FALSE),"")) -> 7311da1a-673f-96b5-66ef-00004409928e | I39: Proxy | J39: High

Sheet Reconciliation
A1: Reconciliation and Later LLM Review
A2: Final fields are resolved independently. Review Required is used only when no ELCD process is available; when an ELCD process is used as a substitute, the match type is Proxy. Existing Direct matches remain Direct.
A3: Metric | B3: Value | D3: Summary | E3: Value
A4: Final normalized material pre-filled | B4: =COUNTIF(QC_Summary!C13:C47,"YES")/35 -> 0.82857143 | D4: Final decision pre-filled | E4: =COUNTIF(QC_Summary!E13:E47,"YES")/35 -> 0.85714286
A5: Final reference process pre-filled | B5: =COUNTIF(QC_Summary!D13:D47,"YES")/35 -> 0.71428571 | D5: Full row agreement | E5: =COUNTIF(QC_Summary!F13:F47,"AGREE")/35 -> 0.57142857
A6: ID | B6: Original BOM Description | C6: Expert A Normalized | D6: Expert A Process | E6: Expert A Decision | F6: Expert B Normalized | G6: Expert B Process | H6: Expert B Decision | I6: Row Status | J6: Final Normalized Material | K6: Final Reference Process | L6: Final Process UUID | M6: Final Decision | N6: LLM Normalized (later) | O6: LLM Process (later) | P6: LLM Decision (later) | Q6: Post-review Outcome | R6: Notes
A7: S01 | B7: Ordinary Portland Cement (OPC 43-grade) | C7: =IF(Expert_A!F5="","",Expert_A!F5) -> Cement | D7: =IF(Expert_A!G5="","",Expert_A!G5) -> Portland cement (CEM I), CEMBUREAU production mix, at plant, CEMBUREAU technology mix, EN 197-1 | RER | 600573dd | E7: =IF(Expert_A!I5="","",Expert_A!I5) -> Direct | F7: =IF(Expert_B!F5="","",Expert_B!F5) -> Cement | G7: =IF(Expert_B!G5="","",Expert_B!G5) -> Portland cement (CEM I), CEMBUREAU production mix, at plant, CEMBUREAU technology mix, EN 197-1 | RER | 600573dd | H7: =IF(Expert_B!I5="","",Expert_B!I5) -> Direct | I7: =IF(OR(C7="",F7="",E7="",H7="",AND(E7<>"Review Required",OR(D7="",LOWER(TRIM(D7))="not available",LOWER(TRIM(D7))="n/a")),AND(H7<>"Review Required",OR(G7="",LOWER(TRIM(G7))="not available",LOWER(TRIM(G7))="n/a"))),"INCOMPLETE",IF(AND(TRIM(C7)=TRIM(F7),TRIM(D7)=TRIM(G7),E7=H7),"AGREE",IF(OR(TRIM(C7)=TRIM(F7),TRIM(D7)=TRIM(G7),E7=H7),"PARTIAL","RECONCILE"))) -> AGREE | J7: =IF(AND(C7<>"",F7<>"",TRIM(C7)=TRIM(F7)),TRIM(C7),"") -> Cement | K7: =IF(AND(D7<>"",G7<>"",D7=G7),D7,"") -> Portland cement (CEM I), CEMBUREAU production mix, at plant, CEMBUREAU technology mix, EN 197-1 | RER | 600573dd | L7: =IF(OR(K7="",LOWER(TRIM(K7))="not available",LOWER(TRIM(K7))="n/a"),"",IFERROR(VLOOKUP(K7,ELCD_Catalog!$A$2:$B$609,2,FALSE),"")) -> 600573dd-dfa5-44e5-b458-8727e793ffd7 | M7: =IF(OR(K7="",LOWER(TRIM(K7))="not available",LOWER(TRIM(K7))="n/a"),"Review Required",IF(AND(E7="Direct",H7="Direct"),"Direct","Proxy")) -> Direct
A8: S02 | B8: River Sand (clean, well-graded) | C8: =IF(Expert_A!F6="","",Expert_A!F6) -> Sand | D8: =IF(Expert_A!G6="","",Expert_A!G6) -> Sand 0/2, production mix, at plant, wet and dry quarry, undried | RER | 898618b1 | E8: =IF(Expert_A!I6="","",Expert_A!I6) -> Direct | F8: =IF(Expert_B!F6="","",Expert_B!F6) -> Sand | G8: =IF(Expert_B!G6="","",Expert_B!G6) -> Sand 0/2, production mix, at plant, wet and dry quarry, undried | RER | 898618b1 | H8: =IF(Expert_B!I6="","",Expert_B!I6) -> Direct | I8: =IF(OR(C8="",F8="",E8="",H8="",AND(E8<>"Review Required",OR(D8="",LOWER(TRIM(D8))="not available",LOWER(TRIM(D8))="n/a")),AND(H8<>"Review Required",OR(G8="",LOWER(TRIM(G8))="not available",LOWER(TRIM(G8))="n/a"))),"INCOMPLETE",IF(AND(TRIM(C8)=TRIM(F8),TRIM(D8)=TRIM(G8),E8=H8),"AGREE",IF(OR(TRIM(C8)=TRIM(F8),TRIM(D8)=TRIM(G8),E8=H8),"PARTIAL","RECONCILE"))) -> AGREE | J8: =IF(AND(C8<>"",F8<>"",TRIM(C8)=TRIM(F8)),TRIM(C8),"") -> Sand | K8: =IF(AND(D8<>"",G8<>"",D8=G8),D8,"") -> Sand 0/2, production mix, at plant, wet and dry quarry, undried | RER | 898618b1 | L8: =IF(OR(K8="",LOWER(TRIM(K8))="not available",LOWER(TRIM(K8))="n/a"),"",IFERROR(VLOOKUP(K8,ELCD_Catalog!$A$2:$B$609,2,FALSE),"")) -> 898618b1-3306-11dd-bd11-0800200c9a66 | M8: =IF(OR(K8="",LOWER(TRIM(K8))="not available",LOWER(TRIM(K8))="n/a"),"Review Required",IF(AND(E8="Direct",H8="Direct"),"Direct","Proxy")) -> Direct
A9: S03 | B9: Natural Gravel | C9: =IF(Expert_A!F7="","",Expert_A!F7) -> Gravel | D9: =IF(Expert_A!G7="","",Expert_A!G7) -> Gravel 2/32, production mix, at plant, wet and dry quarry, undried | RER | 898618b2 | E9: =IF(Expert_A!I7="","",Expert_A!I7) -> Direct | F9: =IF(Expert_B!F7="","",Expert_B!F7) -> Gravel | G9: =IF(Expert_B!G7="","",Expert_B!G7) -> Gravel 2/32, production mix, at plant, wet and dry quarry, undried | RER | 898618b2 | H9: =IF(Expert_B!I7="","",Expert_B!I7) -> Direct | I9: =IF(OR(C9="",F9="",E9="",H9="",AND(E9<>"Review Required",OR(D9="",LOWER(TRIM(D9))="not available",LOWER(TRIM(D9))="n/a")),AND(H9<>"Review Required",OR(G9="",LOWER(TRIM(G9))="not available",LOWER(TRIM(G9))="n/a"))),"INCOMPLETE",IF(AND(TRIM(C9)=TRIM(F9),TRIM(D9)=TRIM(G9),E9=H9),"AGREE",IF(OR(TRIM(C9)=TRIM(F9),TRIM(D9)=TRIM(G9),E9=H9),"PARTIAL","RECONCILE"))) -> AGREE | J9: =IF(AND(C9<>"",F9<>"",TRIM(C9)=TRIM(F9)),TRIM(C9),"") -> Gravel | K9: =IF(AND(D9<>"",G9<>"",D9=G9),D9,"") -> Gravel 2/32, production mix, at plant, wet and dry quarry, undried | RER | 898618b2 | L9: =IF(OR(K9="",LOWER(TRIM(K9))="not available",LOWER(TRIM(K9))="n/a"),"",IFERROR(VLOOKUP(K9,ELCD_Catalog!$A$2:$B$609,2,FALSE),"")) -> 898618b2-3306-11dd-bd11-0800200c9a66 | M9: =IF(OR(K9="",LOWER(TRIM(K9))="not available",LOWER(TRIM(K9))="n/a"),"Review Required",IF(AND(E9="Direct",H9="Direct"),"Direct","Proxy")) -> Direct
A10: S04 | B10: Stone | C10: =IF(Expert_A!F8="","",Expert_A!F8) -> Stone | D10: =IF(Expert_A!G8="","",Expert_A!G8) -> Crushed stone 16/32, production mix, at plant, open pit mining, undried | RER | 898618b3 | E10: =IF(Expert_A!I8="","",Expert_A!I8) -> Proxy | F10: =IF(Expert_B!F8="","",Expert_B!F8) -> Stone | G10: =IF(Expert_B!G8="","",Expert_B!G8) -> Crushed stone 16/32, production mix, at plant, open pit mining, undried | RER | 898618b3 | H10: =IF(Expert_B!I8="","",Expert_B!I8) -> Direct | I10: =IF(OR(C10="",F10="",E10="",H10="",AND(E10<>"Review Required",OR(D10="",LOWER(TRIM(D10))="not available",LOWER(TRIM(D10))="n/a")),AND(H10<>"Review Required",OR(G10="",LOWER(TRIM(G10))="not available",LOWER(TRIM(G10))="n/a"))),"INCOMPLETE",IF(AND(TRIM(C10)=TRIM(F10),TRIM(D10)=TRIM(G10),E10=H10),"AGREE",IF(OR(TRIM(C10)=TRIM(F10),TRIM(D10)=TRIM(G10),E10=H10),"PARTIAL","RECONCILE"))) -> PARTIAL | J10: =IF(AND(C10<>"",F10<>"",TRIM(C10)=TRIM(F10)),TRIM(C10),"") -> Stone | K10: =IF(AND(D10<>"",G10<>"",D10=G10),D10,"") -> Crushed stone 16/32, production mix, at plant, open pit mining, undried | RER | 898618b3 | L10: =IF(OR(K10="",LOWER(TRIM(K10))="not available",LOWER(TRIM(K10))="n/a"),"",IFERROR(VLOOKUP(K10,ELCD_Catalog!$A$2:$B$609,2,FALSE),"")) -> 898618b3-3306-11dd-bd11-0800200c9a66 | M10: =IF(OR(K10="",LOWER(TRIM(K10))="not available",LOWER(TRIM(K10))="n/a"),"Review Required",IF(AND(E10="Direct",H10="Direct"),"Direct","Proxy")) -> Proxy
A11: S05 | B11: Plain Cement Concrete (PCC M10 — 1:3:6) - Binding Layer | C11: =IF(Expert_A!F9="","",Expert_A!F9) -> Concrete | D11: =IF(Expert_A!G9="","",Expert_A!G9) -> Pre-cast concrete, production mix, at plant, minimum reinforcement, concrete type C20/25, without consideration of casings | RER | 898618b0 | E11: =IF(Expert_A!I9="","",Expert_A!I9) -> Direct | F11: =IF(Expert_B!F9="","",Expert_B!F9) -> Concrete | G11: =IF(Expert_B!G9="","",Expert_B!G9) -> Pre-cast concrete, production mix, at plant, minimum reinforcement, concrete type C20/25, without consideration of casings | RER | 898618b0 | H11: =IF(Expert_B!I9="","",Expert_B!I9) -> Proxy | I11: =IF(OR(C11="",F11="",E11="",H11="",AND(E11<>"Review Required",OR(D11="",LOWER(TRIM(D11))="not available",LOWER(TRIM(D11))="n/a")),AND(H11<>"Review Required",OR(G11="",LOWER(TRIM(G11))="not available",LOWER(TRIM(G11))="n/a"))),"INCOMPLETE",IF(AND(TRIM(C11)=TRIM(F11),TRIM(D11)=TRIM(G11),E11=H11),"AGREE",IF(OR(TRIM(C11)=TRIM(F11),TRIM(D11)=TRIM(G11),E11=H11),"PARTIAL","RECONCILE"))) -> PARTIAL | J11: =IF(AND(C11<>"",F11<>"",TRIM(C11)=TRIM(F11)),TRIM(C11),"") -> Concrete | K11: =IF(AND(D11<>"",G11<>"",D11=G11),D11,"") -> Pre-cast concrete, production mix, at plant, minimum reinforcement, concrete type C20/25, without consideration of casings | RER | 898618b0 | L11: =IF(OR(K11="",LOWER(TRIM(K11))="not available",LOWER(TRIM(K11))="n/a"),"",IFERROR(VLOOKUP(K11,ELCD_Catalog!$A$2:$B$609,2,FALSE),"")) -> 898618b0-3306-11dd-bd11-0800200c9a66 | M11: =IF(OR(K11="",LOWER(TRIM(K11))="not available",LOWER(TRIM(K11))="n/a"),"Review Required",IF(AND(E11="Direct",H11="Direct"),"Direct","Proxy")) -> Proxy
A12: S06 | B12: Stonecrete block | C12: =IF(Expert_A!F10="","",Expert_A!F10) -> Concrete block | D12: =IF(Expert_A!G10="","",Expert_A!G10) -> Gypsum stone (CaSO4-dihydrate), production mix, at plant, underground and open pit mining, grinded and purified product | DE | 5adbdfe6 | E12: =IF(Expert_A!I10="","",Expert_A!I10) -> Proxy | F12: =IF(Expert_B!F10="","",Expert_B!F10) -> Block | G12: =IF(Expert_B!G10="","",Expert_B!G10) -> Lightweight concrete block, production mix, at plant, expanded clay as base material | RER | 898618b6 | H12: =IF(Expert_B!I10="","",Expert_B!I10) -> Proxy | I12: =IF(OR(C12="",F12="",E12="",H12="",AND(E12<>"Review Required",OR(D12="",LOWER(TRIM(D12))="not available",LOWER(TRIM(D12))="n/a")),AND(H12<>"Review Required",OR(G12="",LOWER(TRIM(G12))="not available",LOWER(TRIM(G12))="n/a"))),"INCOMPLETE",IF(AND(TRIM(C12)=TRIM(F12),TRIM(D12)=TRIM(G12),E12=H12),"AGREE",IF(OR(TRIM(C12)=TRIM(F12),TRIM(D12)=TRIM(G12),E12=H12),"PARTIAL","RECONCILE"))) -> PARTIAL | J12: Stonecrete Block | K12: Lightweight concrete block, production mix, at plant, expanded clay as base material | RER | 898618b6 | L12: =IF(OR(K12="",LOWER(TRIM(K12))="not available",LOWER(TRIM(K12))="n/a"),"",IFERROR(VLOOKUP(K12,ELCD_Catalog!$A$2:$B$609,2,FALSE),"")) -> 898618b6-3306-11dd-bd11-0800200c9a66 | M12: =IF(OR(K12="",LOWER(TRIM(K12))="not available",LOWER(TRIM(K12))="n/a"),"Review Required",IF(AND(E12="Direct",H12="Direct"),"Direct","Proxy")) -> Proxy
A13: S07 | B13: Rebar TMT Fe500 | C13: =IF(Expert_A!F11="","",Expert_A!F11) -> Rebar | D13: =IF(Expert_A!G11="","",Expert_A!G11) -> Steel rebar, production mix, at plant, blast furnace and electric arc furnace route, | GLO | 268a11fb | E13: =IF(Expert_A!I11="","",Expert_A!I11) -> Direct | F13: =IF(Expert_B!F11="","",Expert_B!F11) -> Rebar | G13: =IF(Expert_B!G11="","",Expert_B!G11) -> Steel rebar, production mix, at plant, blast furnace and electric arc furnace route, | GLO | 268a11fb | H13: =IF(Expert_B!I11="","",Expert_B!I11) -> Direct | I13: =IF(OR(C13="",F13="",E13="",H13="",AND(E13<>"Review Required",OR(D13="",LOWER(TRIM(D13))="not available",LOWER(TRIM(D13))="n/a")),AND(H13<>"Review Required",OR(G13="",LOWER(TRIM(G13))="not available",LOWER(TRIM(G13))="n/a"))),"INCOMPLETE",IF(AND(TRIM(C13)=TRIM(F13),TRIM(D13)=TRIM(G13),E13=H13),"AGREE",IF(OR(TRIM(C13)=TRIM(F13),TRIM(D13)=TRIM(G13),E13=H13),"PARTIAL","RECONCILE"))) -> AGREE | J13: =IF(AND(C13<>"",F13<>"",TRIM(C13)=TRIM(F13)),TRIM(C13),"") -> Rebar | K13: =IF(AND(D13<>"",G13<>"",D13=G13),D13,"") -> Steel rebar, production mix, at plant, blast furnace and electric arc furnace route, | GLO | 268a11fb | L13: =IF(OR(K13="",LOWER(TRIM(K13))="not available",LOWER(TRIM(K13))="n/a"),"",IFERROR(VLOOKUP(K13,ELCD_Catalog!$A$2:$B$609,2,FALSE),"")) -> 268a11fb-baf2-4b9e-8867-38bea0e76ef6 | M13: =IF(OR(K13="",LOWER(TRIM(K13))="not available",LOWER(TRIM(K13))="n/a"),"Review Required",IF(AND(E13="Direct",H13="Direct"),"Direct","Proxy")) -> Direct
A14: S08 | B14: Binding Wire (soft annealed, 18-gauge) | C14: =IF(Expert_A!F12="","",Expert_A!F12) -> Wire | D14: =IF(Expert_A!G12="","",Expert_A!G12) -> Copper wire, consumption mix, at plant, technology mix, cross section 1 mmy | EU-15 | 11bceac4 | E14: =IF(Expert_A!I12="","",Expert_A!I12) -> Proxy | F14: =IF(Expert_B!F12="","",Expert_B!F12) -> Wire | G14: =IF(Expert_B!G12="","",Expert_B!G12) -> Copper wire, consumption mix, at plant, technology mix, cross section 1 mmy | EU-15 | 11bceac4 | H14: =IF(Expert_B!I12="","",Expert_B!I12) -> Proxy | I14: =IF(OR(C14="",F14="",E14="",H14="",AND(E14<>"Review Required",OR(D14="",LOWER(TRIM(D14))="not available",LOWER(TRIM(D14))="n/a")),AND(H14<>"Review Required",OR(G14="",LOWER(TRIM(G14))="not available",LOWER(TRIM(G14))="n/a"))),"INCOMPLETE",IF(AND(TRIM(C14)=TRIM(F14),TRIM(D14)=TRIM(G14),E14=H14),"AGREE",IF(OR(TRIM(C14)=TRIM(F14),TRIM(D14)=TRIM(G14),E14=H14),"PARTIAL","RECONCILE"))) -> AGREE | J14: =IF(AND(C14<>"",F14<>"",TRIM(C14)=TRIM(F14)),TRIM(C14),"") -> Wire | K14: =IF(AND(D14<>"",G14<>"",D14=G14),D14,"") -> Copper wire, consumption mix, at plant, technology mix, cross section 1 mmy | EU-15 | 11bceac4 | L14: =IF(OR(K14="",LOWER(TRIM(K14))="not available",LOWER(TRIM(K14))="n/a"),"",IFERROR(VLOOKUP(K14,ELCD_Catalog!$A$2:$B$609,2,FALSE),"")) -> 11bceac4-b3d8-4048-8e80-b691ecd2c261 | M14: =IF(OR(K14="",LOWER(TRIM(K14))="not available",LOWER(TRIM(K14))="n/a"),"Review Required",IF(AND(E14="Direct",H14="Direct"),"Direct","Proxy")) -> Proxy
A15: S09 | B15: Corrugated Galvanized Iron (CGI) Sheet, 0.45 mm BMT | C15: =IF(Expert_A!F13="","",Expert_A!F13) -> Steel Rolls | D15: =IF(Expert_A!G13="","",Expert_A!G13) -> Steel hot rolled section, production mix, at plant, blast furnace and electric arc furnace route, | GLO | f9d4581e | E15: =IF(Expert_A!I13="","",Expert_A!I13) -> Proxy | F15: =IF(Expert_B!F13="","",Expert_B!F13) -> CGI Sheets | G15: =IF(Expert_B!G13="","",Expert_B!G13) -> corrugated board sheets, production mix, at plant, technology mix, 18% primary fibre, 82 % recycled fibre | EU-27 | 7311da1a | H15: =IF(Expert_B!I13="","",Expert_B!I13) -> Proxy | I15: =IF(OR(C15="",F15="",E15="",H15="",AND(E15<>"Review Required",OR(D15="",LOWER(TRIM(D15))="not available",LOWER(TRIM(D15))="n/a")),AND(H15<>"Review Required",OR(G15="",LOWER(TRIM(G15))="not available",LOWER(TRIM(G15))="n/a"))),"INCOMPLETE",IF(AND(TRIM(C15)=TRIM(F15),TRIM(D15)=TRIM(G15),E15=H15),"AGREE",IF(OR(TRIM(C15)=TRIM(F15),TRIM(D15)=TRIM(G15),E15=H15),"PARTIAL","RECONCILE"))) -> PARTIAL | J15: CGI Sheets | K15: corrugated board sheets, production mix, at plant, technology mix, 18% primary fibre, 82 % recycled fibre | EU-27 | 7311da1a | L15: =IF(OR(K15="",LOWER(TRIM(K15))="not available",LOWER(TRIM(K15))="n/a"),"",IFERROR(VLOOKUP(K15,ELCD_Catalog!$A$2:$B$609,2,FALSE),"")) -> 7311da1a-673f-96b5-66ef-00004409928e | M15: =IF(OR(K15="",LOWER(TRIM(K15))="not available",LOWER(TRIM(K15))="n/a"),"Review Required",IF(AND(E15="Direct",H15="Direct"),"Direct","Proxy")) -> Proxy
A16: S10 | B16: Timber for purlin, rafter, and column post | C16: =IF(Expert_A!F14="","",Expert_A!F14) -> Timber | D16: =IF(Expert_A!G14="","",Expert_A!G14) -> Spruce wood, production mix, at saw mill, timber, 40% water content | DE | 2b61a4d6 | E16: =IF(Expert_A!I14="","",Expert_A!I14) -> Proxy | F16: =IF(Expert_B!F14="","",Expert_B!F14) -> Timber | G16: =IF(Expert_B!G14="","",Expert_B!G14) -> Pine wood, production mix, at saw mill, timber, 40% water content | DE | 621e64d0 | H16: =IF(Expert_B!I14="","",Expert_B!I14) -> Proxy | I16: =IF(OR(C16="",F16="",E16="",H16="",AND(E16<>"Review Required",OR(D16="",LOWER(TRIM(D16))="not available",LOWER(TRIM(D16))="n/a")),AND(H16<>"Review Required",OR(G16="",LOWER(TRIM(G16))="not available",LOWER(TRIM(G16))="n/a"))),"INCOMPLETE",IF(AND(TRIM(C16)=TRIM(F16),TRIM(D16)=TRIM(G16),E16=H16),"AGREE",IF(OR(TRIM(C16)=TRIM(F16),TRIM(D16)=TRIM(G16),E16=H16),"PARTIAL","RECONCILE"))) -> PARTIAL | J16: =IF(AND(C16<>"",F16<>"",TRIM(C16)=TRIM(F16)),TRIM(C16),"") -> Timber | K16: Spruce wood, production mix, at saw mill, timber, 40% water content | DE | 2b61a4d6 | L16: =IF(OR(K16="",LOWER(TRIM(K16))="not available",LOWER(TRIM(K16))="n/a"),"",IFERROR(VLOOKUP(K16,ELCD_Catalog!$A$2:$B$609,2,FALSE),"")) -> 2b61a4d6-bd1d-4ea3-828c-fdbdf5fca1f9 | M16: =IF(OR(K16="",LOWER(TRIM(K16))="not available",LOWER(TRIM(K16))="n/a"),"Review Required",IF(AND(E16="Direct",H16="Direct"),"Direct","Proxy")) -> Proxy
A17: S11 | B17: Plaster 1:4 — External Walls, 15 mm thick | C17: =IF(Expert_A!F15="","",Expert_A!F15) -> Plaster | D17: =IF(Expert_A!G15="","",Expert_A!G15) -> Not available | E17: =IF(Expert_A!I15="","",Expert_A!I15) -> Review Required | F17: =IF(Expert_B!F15="","",Expert_B!F15) -> Plaster | G17: =IF(Expert_B!G15="","",Expert_B!G15) -> Not available | H17: =IF(Expert_B!I15="","",Expert_B!I15) -> Review Required | I17: =IF(OR(C17="",F17="",E17="",H17="",AND(E17<>"Review Required",OR(D17="",LOWER(TRIM(D17))="not available",LOWER(TRIM(D17))="n/a")),AND(H17<>"Review Required",OR(G17="",LOWER(TRIM(G17))="not available",LOWER(TRIM(G17))="n/a"))),"INCOMPLETE",IF(AND(TRIM(C17)=TRIM(F17),TRIM(D17)=TRIM(G17),E17=H17),"AGREE",IF(OR(TRIM(C17)=TRIM(F17),TRIM(D17)=TRIM(G17),E17=H17),"PARTIAL","RECONCILE"))) -> AGREE | J17: =IF(AND(C17<>"",F17<>"",TRIM(C17)=TRIM(F17)),TRIM(C17),"") -> Plaster | K17: Not available | L17: =IF(OR(K17="",LOWER(TRIM(K17))="not available",LOWER(TRIM(K17))="n/a"),"",IFERROR(VLOOKUP(K17,ELCD_Catalog!$A$2:$B$609,2,FALSE),"")) | M17: =IF(OR(K17="",LOWER(TRIM(K17))="not available",LOWER(TRIM(K17))="n/a"),"Review Required",IF(AND(E17="Direct",H17="Direct"),"Direct","Proxy")) -> Review Required
A18: S12 | B18: Plaster 1:6 — Internal Walls, 12 mm thick | C18: =IF(Expert_A!F16="","",Expert_A!F16) -> Plaster | D18: =IF(Expert_A!G16="","",Expert_A!G16) -> Not available | E18: =IF(Expert_A!I16="","",Expert_A!I16) -> Review Required | F18: =IF(Expert_B!F16="","",Expert_B!F16) -> Plaster | G18: =IF(Expert_B!G16="","",Expert_B!G16) -> Not available | H18: =IF(Expert_B!I16="","",Expert_B!I16) -> Review Required | I18: =IF(OR(C18="",F18="",E18="",H18="",AND(E18<>"Review Required",OR(D18="",LOWER(TRIM(D18))="not available",LOWER(TRIM(D18))="n/a")),AND(H18<>"Review Required",OR(G18="",LOWER(TRIM(G18))="not available",LOWER(TRIM(G18))="n/a"))),"INCOMPLETE",IF(AND(TRIM(C18)=TRIM(F18),TRIM(D18)=TRIM(G18),E18=H18),"AGREE",IF(OR(TRIM(C18)=TRIM(F18),TRIM(D18)=TRIM(G18),E18=H18),"PARTIAL","RECONCILE"))) -> AGREE | J18: =IF(AND(C18<>"",F18<>"",TRIM(C18)=TRIM(F18)),TRIM(C18),"") -> Plaster | K18: Not available | L18: =IF(OR(K18="",LOWER(TRIM(K18))="not available",LOWER(TRIM(K18))="n/a"),"",IFERROR(VLOOKUP(K18,ELCD_Catalog!$A$2:$B$609,2,FALSE),"")) | M18: =IF(OR(K18="",LOWER(TRIM(K18))="not available",LOWER(TRIM(K18))="n/a"),"Review Required",IF(AND(E18="Direct",H18="Direct"),"Direct","Proxy")) -> Review Required
A19: B01 | B19: Cement | C19: =IF(Expert_A!F17="","",Expert_A!F17) -> Cement | D19: =IF(Expert_A!G17="","",Expert_A!G17) -> Portland cement (CEM I), CEMBUREAU production mix, at plant, CEMBUREAU technology mix, EN 197-1 | RER | 600573dd | E19: =IF(Expert_A!I17="","",Expert_A!I17) -> Direct | F19: =IF(Expert_B!F17="","",Expert_B!F17) -> Cement | G19: =IF(Expert_B!G17="","",Expert_B!G17) -> Portland cement (CEM I), CEMBUREAU production mix, at plant, CEMBUREAU technology mix, EN 197-1 | RER | 600573dd | H19: =IF(Expert_B!I17="","",Expert_B!I17) -> Direct | I19: =IF(OR(C19="",F19="",E19="",H19="",AND(E19<>"Review Required",OR(D19="",LOWER(TRIM(D19))="not available",LOWER(TRIM(D19))="n/a")),AND(H19<>"Review Required",OR(G19="",LOWER(TRIM(G19))="not available",LOWER(TRIM(G19))="n/a"))),"INCOMPLETE",IF(AND(TRIM(C19)=TRIM(F19),TRIM(D19)=TRIM(G19),E19=H19),"AGREE",IF(OR(TRIM(C19)=TRIM(F19),TRIM(D19)=TRIM(G19),E19=H19),"PARTIAL","RECONCILE"))) -> AGREE | J19: =IF(AND(C19<>"",F19<>"",TRIM(C19)=TRIM(F19)),TRIM(C19),"") -> Cement | K19: =IF(AND(D19<>"",G19<>"",D19=G19),D19,"") -> Portland cement (CEM I), CEMBUREAU production mix, at plant, CEMBUREAU technology mix, EN 197-1 | RER | 600573dd | L19: =IF(OR(K19="",LOWER(TRIM(K19))="not available",LOWER(TRIM(K19))="n/a"),"",IFERROR(VLOOKUP(K19,ELCD_Catalog!$A$2:$B$609,2,FALSE),"")) -> 600573dd-dfa5-44e5-b458-8727e793ffd7 | M19: =IF(OR(K19="",LOWER(TRIM(K19))="not available",LOWER(TRIM(K19))="n/a"),"Review Required",IF(AND(E19="Direct",H19="Direct"),"Direct","Proxy")) -> Direct
A20: B02 | B20: Sand | C20: =IF(Expert_A!F18="","",Expert_A!F18) -> Sand | D20: =IF(Expert_A!G18="","",Expert_A!G18) -> Sand 0/2, production mix, at plant, wet and dry quarry, undried | RER | 898618b1 | E20: =IF(Expert_A!I18="","",Expert_A!I18) -> Direct | F20: =IF(Expert_B!F18="","",Expert_B!F18) -> Sand | G20: =IF(Expert_B!G18="","",Expert_B!G18) -> Sand 0/2, production mix, at plant, wet and dry quarry, undried | RER | 898618b1 | H20: =IF(Expert_B!I18="","",Expert_B!I18) -> Direct | I20: =IF(OR(C20="",F20="",E20="",H20="",AND(E20<>"Review Required",OR(D20="",LOWER(TRIM(D20))="not available",LOWER(TRIM(D20))="n/a")),AND(H20<>"Review Required",OR(G20="",LOWER(TRIM(G20))="not available",LOWER(TRIM(G20))="n/a"))),"INCOMPLETE",IF(AND(TRIM(C20)=TRIM(F20),TRIM(D20)=TRIM(G20),E20=H20),"AGREE",IF(OR(TRIM(C20)=TRIM(F20),TRIM(D20)=TRIM(G20),E20=H20),"PARTIAL","RECONCILE"))) -> AGREE | J20: =IF(AND(C20<>"",F20<>"",TRIM(C20)=TRIM(F20)),TRIM(C20),"") -> Sand | K20: =IF(AND(D20<>"",G20<>"",D20=G20),D20,"") -> Sand 0/2, production mix, at plant, wet and dry quarry, undried | RER | 898618b1 | L20: =IF(OR(K20="",LOWER(TRIM(K20))="not available",LOWER(TRIM(K20))="n/a"),"",IFERROR(VLOOKUP(K20,ELCD_Catalog!$A$2:$B$609,2,FALSE),"")) -> 898618b1-3306-11dd-bd11-0800200c9a66 | M20: =IF(OR(K20="",LOWER(TRIM(K20))="not available",LOWER(TRIM(K20))="n/a"),"Review Required",IF(AND(E20="Direct",H20="Direct"),"Direct","Proxy")) -> Direct
A21: B03 | B21: Natural Gravel | C21: =IF(Expert_A!F19="","",Expert_A!F19) -> Gravel | D21: =IF(Expert_A!G19="","",Expert_A!G19) -> Gravel 2/32, production mix, at plant, wet and dry quarry, undried | RER | 898618b2 | E21: =IF(Expert_A!I19="","",Expert_A!I19) -> Direct | F21: =IF(Expert_B!F19="","",Expert_B!F19) -> Gravel | G21: =IF(Expert_B!G19="","",Expert_B!G19) -> Gravel 2/32, production mix, at plant, wet and dry quarry, undried | RER | 898618b2 | H21: =IF(Expert_B!I19="","",Expert_B!I19) -> Direct | I21: =IF(OR(C21="",F21="",E21="",H21="",AND(E21<>"Review Required",OR(D21="",LOWER(TRIM(D21))="not available",LOWER(TRIM(D21))="n/a")),AND(H21<>"Review Required",OR(G21="",LOWER(TRIM(G21))="not available",LOWER(TRIM(G21))="n/a"))),"INCOMPLETE",IF(AND(TRIM(C21)=TRIM(F21),TRIM(D21)=TRIM(G21),E21=H21),"AGREE",IF(OR(TRIM(C21)=TRIM(F21),TRIM(D21)=TRIM(G21),E21=H21),"PARTIAL","RECONCILE"))) -> AGREE | J21: =IF(AND(C21<>"",F21<>"",TRIM(C21)=TRIM(F21)),TRIM(C21),"") -> Gravel | K21: =IF(AND(D21<>"",G21<>"",D21=G21),D21,"") -> Gravel 2/32, production mix, at plant, wet and dry quarry, undried | RER | 898618b2 | L21: =IF(OR(K21="",LOWER(TRIM(K21))="not available",LOWER(TRIM(K21))="n/a"),"",IFERROR(VLOOKUP(K21,ELCD_Catalog!$A$2:$B$609,2,FALSE),"")) -> 898618b2-3306-11dd-bd11-0800200c9a66 | M21: =IF(OR(K21="",LOWER(TRIM(K21))="not available",LOWER(TRIM(K21))="n/a"),"Review Required",IF(AND(E21="Direct",H21="Direct"),"Direct","Proxy")) -> Direct
A22: B04 | B22: Stone | C22: =IF(Expert_A!F20="","",Expert_A!F20) -> Stone | D22: =IF(Expert_A!G20="","",Expert_A!G20) -> Crushed stone 16/32, production mix, at plant, open pit mining, undried | RER | 898618b3 | E22: =IF(Expert_A!I20="","",Expert_A!I20) -> Proxy | F22: =IF(Expert_B!F20="","",Expert_B!F20) -> Stone | G22: =IF(Expert_B!G20="","",Expert_B!G20) -> Crushed stone 16/32, production mix, at plant, open pit mining, undried | RER | 898618b3 | H22: =IF(Expert_B!I20="","",Expert_B!I20) -> Direct | I22: =IF(OR(C22="",F22="",E22="",H22="",AND(E22<>"Review Required",OR(D22="",LOWER(TRIM(D22))="not available",LOWER(TRIM(D22))="n/a")),AND(H22<>"Review Required",OR(G22="",LOWER(TRIM(G22))="not available",LOWER(TRIM(G22))="n/a"))),"INCOMPLETE",IF(AND(TRIM(C22)=TRIM(F22),TRIM(D22)=TRIM(G22),E22=H22),"AGREE",IF(OR(TRIM(C22)=TRIM(F22),TRIM(D22)=TRIM(G22),E22=H22),"PARTIAL","RECONCILE"))) -> PARTIAL | J22: =IF(AND(C22<>"",F22<>"",TRIM(C22)=TRIM(F22)),TRIM(C22),"") -> Stone | K22: =IF(AND(D22<>"",G22<>"",D22=G22),D22,"") -> Crushed stone 16/32, production mix, at plant, open pit mining, undried | RER | 898618b3 | L22: =IF(OR(K22="",LOWER(TRIM(K22))="not available",LOWER(TRIM(K22))="n/a"),"",IFERROR(VLOOKUP(K22,ELCD_Catalog!$A$2:$B$609,2,FALSE),"")) -> 898618b3-3306-11dd-bd11-0800200c9a66 | M22: =IF(OR(K22="",LOWER(TRIM(K22))="not available",LOWER(TRIM(K22))="n/a"),"Review Required",IF(AND(E22="Direct",H22="Direct"),"Direct","Proxy")) -> Proxy
A23: B05 | B23: Soil | C23: =IF(Expert_A!F21="","",Expert_A!F21) -> Soil | D23: =IF(Expert_A!G21="","",Expert_A!G21) -> Not available | E23: =IF(Expert_A!I21="","",Expert_A!I21) -> Review Required | F23: =IF(Expert_B!F21="","",Expert_B!F21) -> Soil | G23: =IF(Expert_B!G21="","",Expert_B!G21) -> Not available | H23: =IF(Expert_B!I21="","",Expert_B!I21) -> Review Required | I23: =IF(OR(C23="",F23="",E23="",H23="",AND(E23<>"Review Required",OR(D23="",LOWER(TRIM(D23))="not available",LOWER(TRIM(D23))="n/a")),AND(H23<>"Review Required",OR(G23="",LOWER(TRIM(G23))="not available",LOWER(TRIM(G23))="n/a"))),"INCOMPLETE",IF(AND(TRIM(C23)=TRIM(F23),TRIM(D23)=TRIM(G23),E23=H23),"AGREE",IF(OR(TRIM(C23)=TRIM(F23),TRIM(D23)=TRIM(G23),E23=H23),"PARTIAL","RECONCILE"))) -> AGREE | J23: =IF(AND(C23<>"",F23<>"",TRIM(C23)=TRIM(F23)),TRIM(C23),"") -> Soil | K23: Not available | L23: =IF(OR(K23="",LOWER(TRIM(K23))="not available",LOWER(TRIM(K23))="n/a"),"",IFERROR(VLOOKUP(K23,ELCD_Catalog!$A$2:$B$609,2,FALSE),"")) | M23: =IF(OR(K23="",LOWER(TRIM(K23))="not available",LOWER(TRIM(K23))="n/a"),"Review Required",IF(AND(E23="Direct",H23="Direct"),"Direct","Proxy")) -> Review Required
A24: B06 | B24: Local Wood | C24: =IF(Expert_A!F22="","",Expert_A!F22) -> Wood | D24: =IF(Expert_A!G22="","",Expert_A!G22) -> Pine wood, production mix, at saw mill, timber, 40% water content | DE | 621e64d0 | E24: =IF(Expert_A!I22="","",Expert_A!I22) -> Proxy | F24: =IF(Expert_B!F22="","",Expert_B!F22) -> Wood | G24: =IF(Expert_B!G22="","",Expert_B!G22) -> Spruce wood, production mix, at saw mill, timber, 40% water content | DE | 2b61a4d6 | H24: =IF(Expert_B!I22="","",Expert_B!I22) -> Proxy | I24: =IF(OR(C24="",F24="",E24="",H24="",AND(E24<>"Review Required",OR(D24="",LOWER(TRIM(D24))="not available",LOWER(TRIM(D24))="n/a")),AND(H24<>"Review Required",OR(G24="",LOWER(TRIM(G24))="not available",LOWER(TRIM(G24))="n/a"))),"INCOMPLETE",IF(AND(TRIM(C24)=TRIM(F24),TRIM(D24)=TRIM(G24),E24=H24),"AGREE",IF(OR(TRIM(C24)=TRIM(F24),TRIM(D24)=TRIM(G24),E24=H24),"PARTIAL","RECONCILE"))) -> PARTIAL | J24: =IF(AND(C24<>"",F24<>"",TRIM(C24)=TRIM(F24)),TRIM(C24),"") -> Wood | K24: Spruce wood, production mix, at saw mill, timber, 40% water content | DE | 2b61a4d6 | L24: =IF(OR(K24="",LOWER(TRIM(K24))="not available",LOWER(TRIM(K24))="n/a"),"",IFERROR(VLOOKUP(K24,ELCD_Catalog!$A$2:$B$609,2,FALSE),"")) -> 2b61a4d6-bd1d-4ea3-828c-fdbdf5fca1f9 | M24: =IF(OR(K24="",LOWER(TRIM(K24))="not available",LOWER(TRIM(K24))="n/a"),"Review Required",IF(AND(E24="Direct",H24="Direct"),"Direct","Proxy")) -> Proxy
A25: B07 | B25: 19mm Plywood | C25: =IF(Expert_A!F23="","",Expert_A!F23) -> Plywood | D25: =IF(Expert_A!G23="","",Expert_A!G23) -> Pine wood, production mix, at saw mill, timber, 40% water content | DE | 621e64d0 | E25: =IF(Expert_A!I23="","",Expert_A!I23) -> Proxy | F25: =IF(Expert_B!F23="","",Expert_B!F23) -> Plywood | G25: =IF(Expert_B!G23="","",Expert_B!G23) -> Waste incineration of wood products (OSB, particle board), at plant, average European waste-to-energy plant, without collection, transport and pre-treatment | EU-27 | 39f61d7a | H25: =IF(Expert_B!I23="","",Expert_B!I23) -> Proxy | I25: =IF(OR(C25="",F25="",E25="",H25="",AND(E25<>"Review Required",OR(D25="",LOWER(TRIM(D25))="not available",LOWER(TRIM(D25))="n/a")),AND(H25<>"Review Required",OR(G25="",LOWER(TRIM(G25))="not available",LOWER(TRIM(G25))="n/a"))),"INCOMPLETE",IF(AND(TRIM(C25)=TRIM(F25),TRIM(D25)=TRIM(G25),E25=H25),"AGREE",IF(OR(TRIM(C25)=TRIM(F25),TRIM(D25)=TRIM(G25),E25=H25),"PARTIAL","RECONCILE"))) -> PARTIAL | J25: =IF(AND(C25<>"",F25<>"",TRIM(C25)=TRIM(F25)),TRIM(C25),"") -> Plywood | K25: Pine wood, production mix, at saw mill, timber, 40% water content | DE | 621e64d0 | L25: =IF(OR(K25="",LOWER(TRIM(K25))="not available",LOWER(TRIM(K25))="n/a"),"",IFERROR(VLOOKUP(K25,ELCD_Catalog!$A$2:$B$609,2,FALSE),"")) -> 621e64d0-f471-4023-9ebc-a52cd8ee573f | M25: =IF(OR(K25="",LOWER(TRIM(K25))="not available",LOWER(TRIM(K25))="n/a"),"Review Required",IF(AND(E25="Direct",H25="Direct"),"Direct","Proxy")) -> Proxy
A26: B08 | B26: Nail | C26: =IF(Expert_A!F24="","",Expert_A!F24) -> Steel nail | D26: =IF(Expert_A!G24="","",Expert_A!G24) -> Not available | E26: =IF(Expert_A!I24="","",Expert_A!I24) -> Review Required | F26: =IF(Expert_B!F24="","",Expert_B!F24) -> Nail | G26: =IF(Expert_B!G24="","",Expert_B!G24) -> Not available | H26: =IF(Expert_B!I24="","",Expert_B!I24) -> Review Required | I26: =IF(OR(C26="",F26="",E26="",H26="",AND(E26<>"Review Required",OR(D26="",LOWER(TRIM(D26))="not available",LOWER(TRIM(D26))="n/a")),AND(H26<>"Review Required",OR(G26="",LOWER(TRIM(G26))="not available",LOWER(TRIM(G26))="n/a"))),"INCOMPLETE",IF(AND(TRIM(C26)=TRIM(F26),TRIM(D26)=TRIM(G26),E26=H26),"AGREE",IF(OR(TRIM(C26)=TRIM(F26),TRIM(D26)=TRIM(G26),E26=H26),"PARTIAL","RECONCILE"))) -> PARTIAL | J26: Steel nail | K26: Not available | L26: =IF(OR(K26="",LOWER(TRIM(K26))="not available",LOWER(TRIM(K26))="n/a"),"",IFERROR(VLOOKUP(K26,ELCD_Catalog!$A$2:$B$609,2,FALSE),"")) | M26: =IF(OR(K26="",LOWER(TRIM(K26))="not available",LOWER(TRIM(K26))="n/a"),"Review Required",IF(AND(E26="Direct",H26="Direct"),"Direct","Proxy")) -> Review Required
A27: B09 | B27: 10mm Rebar | C27: =IF(Expert_A!F25="","",Expert_A!F25) -> Rebar | D27: =IF(Expert_A!G25="","",Expert_A!G25) -> Steel rebar, production mix, at plant, blast furnace and electric arc furnace route, | GLO | 268a11fb | E27: =IF(Expert_A!I25="","",Expert_A!I25) -> Direct | F27: =IF(Expert_B!F25="","",Expert_B!F25) -> Rebar | G27: =IF(Expert_B!G25="","",Expert_B!G25) -> Steel rebar, production mix, at plant, blast furnace and electric arc furnace route, | GLO | 268a11fb | H27: =IF(Expert_B!I25="","",Expert_B!I25) -> Direct | I27: =IF(OR(C27="",F27="",E27="",H27="",AND(E27<>"Review Required",OR(D27="",LOWER(TRIM(D27))="not available",LOWER(TRIM(D27))="n/a")),AND(H27<>"Review Required",OR(G27="",LOWER(TRIM(G27))="not available",LOWER(TRIM(G27))="n/a"))),"INCOMPLETE",IF(AND(TRIM(C27)=TRIM(F27),TRIM(D27)=TRIM(G27),E27=H27),"AGREE",IF(OR(TRIM(C27)=TRIM(F27),TRIM(D27)=TRIM(G27),E27=H27),"PARTIAL","RECONCILE"))) -> AGREE | J27: =IF(AND(C27<>"",F27<>"",TRIM(C27)=TRIM(F27)),TRIM(C27),"") -> Rebar | K27: =IF(AND(D27<>"",G27<>"",D27=G27),D27,"") -> Steel rebar, production mix, at plant, blast furnace and electric arc furnace route, | GLO | 268a11fb | L27: =IF(OR(K27="",LOWER(TRIM(K27))="not available",LOWER(TRIM(K27))="n/a"),"",IFERROR(VLOOKUP(K27,ELCD_Catalog!$A$2:$B$609,2,FALSE),"")) -> 268a11fb-baf2-4b9e-8867-38bea0e76ef6 | M27: =IF(OR(K27="",LOWER(TRIM(K27))="not available",LOWER(TRIM(K27))="n/a"),"Review Required",IF(AND(E27="Direct",H27="Direct"),"Direct","Proxy")) -> Direct
A28: B10 | B28: 7mm Rebar | C28: =IF(Expert_A!F26="","",Expert_A!F26) -> Rebar | D28: =IF(Expert_A!G26="","",Expert_A!G26) -> Steel rebar, production mix, at plant, blast furnace and electric arc furnace route, | GLO | 268a11fb | E28: =IF(Expert_A!I26="","",Expert_A!I26) -> Direct | F28: =IF(Expert_B!F26="","",Expert_B!F26) -> Rebar | G28: =IF(Expert_B!G26="","",Expert_B!G26) -> Steel rebar, production mix, at plant, blast furnace and electric arc furnace route, | GLO | 268a11fb | H28: =IF(Expert_B!I26="","",Expert_B!I26) -> Direct | I28: =IF(OR(C28="",F28="",E28="",H28="",AND(E28<>"Review Required",OR(D28="",LOWER(TRIM(D28))="not available",LOWER(TRIM(D28))="n/a")),AND(H28<>"Review Required",OR(G28="",LOWER(TRIM(G28))="not available",LOWER(TRIM(G28))="n/a"))),"INCOMPLETE",IF(AND(TRIM(C28)=TRIM(F28),TRIM(D28)=TRIM(G28),E28=H28),"AGREE",IF(OR(TRIM(C28)=TRIM(F28),TRIM(D28)=TRIM(G28),E28=H28),"PARTIAL","RECONCILE"))) -> AGREE | J28: =IF(AND(C28<>"",F28<>"",TRIM(C28)=TRIM(F28)),TRIM(C28),"") -> Rebar | K28: =IF(AND(D28<>"",G28<>"",D28=G28),D28,"") -> Steel rebar, production mix, at plant, blast furnace and electric arc furnace route, | GLO | 268a11fb | L28: =IF(OR(K28="",LOWER(TRIM(K28))="not available",LOWER(TRIM(K28))="n/a"),"",IFERROR(VLOOKUP(K28,ELCD_Catalog!$A$2:$B$609,2,FALSE),"")) -> 268a11fb-baf2-4b9e-8867-38bea0e76ef6 | M28: =IF(OR(K28="",LOWER(TRIM(K28))="not available",LOWER(TRIM(K28))="n/a"),"Review Required",IF(AND(E28="Direct",H28="Direct"),"Direct","Proxy")) -> Direct
A29: B11 | B29: Binding Wire | C29: =IF(Expert_A!F27="","",Expert_A!F27) -> Wire | D29: =IF(Expert_A!G27="","",Expert_A!G27) -> Copper wire; technology mix; market mix, at plant; cross section 1 mm, Technology and Market Mix for Wire fabrication representing main European production countries, Market Mix for Copper cathode in Europe (primary and secondary Cu cathode production... | EU-25 | 819e60d3 | E29: =IF(Expert_A!I27="","",Expert_A!I27) -> Proxy | F29: =IF(Expert_B!F27="","",Expert_B!F27) -> Wire | G29: =IF(Expert_B!G27="","",Expert_B!G27) -> Copper wire, consumption mix, at plant, technology mix, cross section 1 mmy | EU-15 | 11bceac4 | H29: =IF(Expert_B!I27="","",Expert_B!I27) -> Direct | I29: =IF(OR(C29="",F29="",E29="",H29="",AND(E29<>"Review Required",OR(D29="",LOWER(TRIM(D29))="not available",LOWER(TRIM(D29))="n/a")),AND(H29<>"Review Required",OR(G29="",LOWER(TRIM(G29))="not available",LOWER(TRIM(G29))="n/a"))),"INCOMPLETE",IF(AND(TRIM(C29)=TRIM(F29),TRIM(D29)=TRIM(G29),E29=H29),"AGREE",IF(OR(TRIM(C29)=TRIM(F29),TRIM(D29)=TRIM(G29),E29=H29),"PARTIAL","RECONCILE"))) -> PARTIAL | J29: =IF(AND(C29<>"",F29<>"",TRIM(C29)=TRIM(F29)),TRIM(C29),"") -> Wire | K29: Copper wire, consumption mix, at plant, technology mix, cross section 1 mmy | EU-15 | 11bceac4 | L29: =IF(OR(K29="",LOWER(TRIM(K29))="not available",LOWER(TRIM(K29))="n/a"),"",IFERROR(VLOOKUP(K29,ELCD_Catalog!$A$2:$B$609,2,FALSE),"")) -> 11bceac4-b3d8-4048-8e80-b691ecd2c261 | M29: =IF(OR(K29="",LOWER(TRIM(K29))="not available",LOWER(TRIM(K29))="n/a"),"Review Required",IF(AND(E29="Direct",H29="Direct"),"Direct","Proxy")) -> Proxy
A30: B12 | B30: 24 Gauge CGI Sheets | C30: =IF(Expert_A!F28="","",Expert_A!F28) -> Steel Rolls | D30: =IF(Expert_A!G28="","",Expert_A!G28) -> Steel hot rolled coil, production mix, at plant, blast furnace route, thickness 2 to 7 mm, width 600 to 2100 mm | RER | 119e8cc1 | E30: =IF(Expert_A!I28="","",Expert_A!I28) -> Proxy | F30: =IF(Expert_B!F28="","",Expert_B!F28) -> CGI Sheets | G30: =IF(Expert_B!G28="","",Expert_B!G28) -> corrugated board sheets, production mix, at plant, technology mix, 18% primary fibre, 82 % recycled fibre | EU-27 | 7311da1a | H30: =IF(Expert_B!I28="","",Expert_B!I28) -> Proxy | I30: =IF(OR(C30="",F30="",E30="",H30="",AND(E30<>"Review Required",OR(D30="",LOWER(TRIM(D30))="not available",LOWER(TRIM(D30))="n/a")),AND(H30<>"Review Required",OR(G30="",LOWER(TRIM(G30))="not available",LOWER(TRIM(G30))="n/a"))),"INCOMPLETE",IF(AND(TRIM(C30)=TRIM(F30),TRIM(D30)=TRIM(G30),E30=H30),"AGREE",IF(OR(TRIM(C30)=TRIM(F30),TRIM(D30)=TRIM(G30),E30=H30),"PARTIAL","RECONCILE"))) -> PARTIAL | J30: CGI Sheets | K30: corrugated board sheets, production mix, at plant, technology mix, 18% primary fibre, 82 % recycled fibre | EU-27 | 7311da1a | L30: =IF(OR(K30="",LOWER(TRIM(K30))="not available",LOWER(TRIM(K30))="n/a"),"",IFERROR(VLOOKUP(K30,ELCD_Catalog!$A$2:$B$609,2,FALSE),"")) -> 7311da1a-673f-96b5-66ef-00004409928e | M30: =IF(OR(K30="",LOWER(TRIM(K30))="not available",LOWER(TRIM(K30))="n/a"),"Review Required",IF(AND(E30="Direct",H30="Direct"),"Direct","Proxy")) -> Proxy
A31: B13 | B31: 3mm Commercial Plywood | C31: =IF(Expert_A!F29="","",Expert_A!F29) -> Plywood | D31: =IF(Expert_A!G29="","",Expert_A!G29) -> Pine wood, production mix, at saw mill, timber, 40% water content | DE | 621e64d0 | E31: =IF(Expert_A!I29="","",Expert_A!I29) -> Proxy | F31: =IF(Expert_B!F29="","",Expert_B!F29) -> Plywood | G31: =IF(Expert_B!G29="","",Expert_B!G29) -> Landfill of wood products (OSB, particle board), at landfill site, landfill including landfill gas utilisation and leachate treatment and without collection, transport and pre-treatment | EU-27 | 64197303 | H31: =IF(Expert_B!I29="","",Expert_B!I29) -> Proxy | I31: =IF(OR(C31="",F31="",E31="",H31="",AND(E31<>"Review Required",OR(D31="",LOWER(TRIM(D31))="not available",LOWER(TRIM(D31))="n/a")),AND(H31<>"Review Required",OR(G31="",LOWER(TRIM(G31))="not available",LOWER(TRIM(G31))="n/a"))),"INCOMPLETE",IF(AND(TRIM(C31)=TRIM(F31),TRIM(D31)=TRIM(G31),E31=H31),"AGREE",IF(OR(TRIM(C31)=TRIM(F31),TRIM(D31)=TRIM(G31),E31=H31),"PARTIAL","RECONCILE"))) -> PARTIAL | J31: =IF(AND(C31<>"",F31<>"",TRIM(C31)=TRIM(F31)),TRIM(C31),"") -> Plywood | K31: Pine wood, production mix, at saw mill, timber, 40% water content | DE | 621e64d0 | L31: =IF(OR(K31="",LOWER(TRIM(K31))="not available",LOWER(TRIM(K31))="n/a"),"",IFERROR(VLOOKUP(K31,ELCD_Catalog!$A$2:$B$609,2,FALSE),"")) -> 621e64d0-f471-4023-9ebc-a52cd8ee573f | M31: =IF(OR(K31="",LOWER(TRIM(K31))="not available",LOWER(TRIM(K31))="n/a"),"Review Required",IF(AND(E31="Direct",H31="Direct"),"Direct","Proxy")) -> Proxy
A32: B14 | B32: Bamboo | C32: =IF(Expert_A!F30="","",Expert_A!F30) -> Bamboo | D32: =IF(Expert_A!G30="","",Expert_A!G30) -> Not available | E32: =IF(Expert_A!I30="","",Expert_A!I30) -> Review Required | F32: =IF(Expert_B!F30="","",Expert_B!F30) -> Bamboo | G32: =IF(Expert_B!G30="","",Expert_B!G30) -> Not available | H32: =IF(Expert_B!I30="","",Expert_B!I30) -> Review Required | I32: =IF(OR(C32="",F32="",E32="",H32="",AND(E32<>"Review Required",OR(D32="",LOWER(TRIM(D32))="not available",LOWER(TRIM(D32))="n/a")),AND(H32<>"Review Required",OR(G32="",LOWER(TRIM(G32))="not available",LOWER(TRIM(G32))="n/a"))),"INCOMPLETE",IF(AND(TRIM(C32)=TRIM(F32),TRIM(D32)=TRIM(G32),E32=H32),"AGREE",IF(OR(TRIM(C32)=TRIM(F32),TRIM(D32)=TRIM(G32),E32=H32),"PARTIAL","RECONCILE"))) -> AGREE | J32: =IF(AND(C32<>"",F32<>"",TRIM(C32)=TRIM(F32)),TRIM(C32),"") -> Bamboo | K32: Not available | L32: =IF(OR(K32="",LOWER(TRIM(K32))="not available",LOWER(TRIM(K32))="n/a"),"",IFERROR(VLOOKUP(K32,ELCD_Catalog!$A$2:$B$609,2,FALSE),"")) | M32: =IF(OR(K32="",LOWER(TRIM(K32))="not available",LOWER(TRIM(K32))="n/a"),"Review Required",IF(AND(E32="Direct",H32="Direct"),"Direct","Proxy")) -> Review Required
A33: A01 | B33: Cement | C33: =IF(Expert_A!F31="","",Expert_A!F31) -> Cement | D33: =IF(Expert_A!G31="","",Expert_A!G31) -> Portland cement (CEM I), CEMBUREAU production mix, at plant, CEMBUREAU technology mix, EN 197-1 | RER | 600573dd | E33: =IF(Expert_A!I31="","",Expert_A!I31) -> Direct | F33: =IF(Expert_B!F31="","",Expert_B!F31) -> Cement | G33: =IF(Expert_B!G31="","",Expert_B!G31) -> Portland cement (CEM I), CEMBUREAU production mix, at plant, CEMBUREAU technology mix, EN 197-1 | RER | 600573dd | H33: =IF(Expert_B!I31="","",Expert_B!I31) -> Direct | I33: =IF(OR(C33="",F33="",E33="",H33="",AND(E33<>"Review Required",OR(D33="",LOWER(TRIM(D33))="not available",LOWER(TRIM(D33))="n/a")),AND(H33<>"Review Required",OR(G33="",LOWER(TRIM(G33))="not available",LOWER(TRIM(G33))="n/a"))),"INCOMPLETE",IF(AND(TRIM(C33)=TRIM(F33),TRIM(D33)=TRIM(G33),E33=H33),"AGREE",IF(OR(TRIM(C33)=TRIM(F33),TRIM(D33)=TRIM(G33),E33=H33),"PARTIAL","RECONCILE"))) -> AGREE | J33: =IF(AND(C33<>"",F33<>"",TRIM(C33)=TRIM(F33)),TRIM(C33),"") -> Cement | K33: =IF(AND(D33<>"",G33<>"",D33=G33),D33,"") -> Portland cement (CEM I), CEMBUREAU production mix, at plant, CEMBUREAU technology mix, EN 197-1 | RER | 600573dd | L33: =IF(OR(K33="",LOWER(TRIM(K33))="not available",LOWER(TRIM(K33))="n/a"),"",IFERROR(VLOOKUP(K33,ELCD_Catalog!$A$2:$B$609,2,FALSE),"")) -> 600573dd-dfa5-44e5-b458-8727e793ffd7 | M33: =IF(OR(K33="",LOWER(TRIM(K33))="not available",LOWER(TRIM(K33))="n/a"),"Review Required",IF(AND(E33="Direct",H33="Direct"),"Direct","Proxy")) -> Direct
